<?xml version="1.0" encoding="utf-8"?>
<robot
  name="cr20_robot" xmlns:xacro="http://ros.org/wiki/xacro">
  <link name="dummy_link"/>
  <link
    name="base_link">
    <inertial>
      <origin
        xyz="-0.0523349568972135 0.0899270486094572 -0.00279275668479641"
        rpy="0 0 0" />
      <mass
        value="0.00264393848129463" />
      <inertia
        ixx="0"
        ixy="0"
        ixz="0"
        iyy="0"
        iyz="0"
        izz="0" />
    </inertial>
    <visual>
      <origin
        xyz="0 0 0"
        rpy="0 0 0" />
      <geometry>
        <mesh
          filename="file://$(find cra_description)/meshes/cr20/base_link.STL" />
      </geometry>
      <material
        name="">
        <color
          rgba="0.792156862745098 0.819607843137255 0.933333333333333 1" />
      </material>
    </visual>
    <collision>
      <origin
        xyz="0 0 0"
        rpy="0 0 0" />
      <geometry>
        <mesh
          filename="file://$(find cra_description)/meshes/cr20/base_link.STL" />
      </geometry>
    </collision>
  </link>
    <link  name="world"/>
  <joint name="world_joint" type="fixed">
    <parent link="world" />
    <child  link="dummy_link" />
  </joint>
  <joint name="dummy_joint" type="fixed">
    <parent link="dummy_link" />
    <child  link="base_link" />
  </joint>
  <link
    name="Link1">
    <inertial>
      <origin
        xyz="-0.0154576425326206 -0.0986375365415087 1.04119647925812"
        rpy="0 0 0" />
      <mass
        value="0.00895254328755396" />
      <inertia
        ixx="0"
        ixy="0"
        ixz="0"
        iyy="0"
        iyz="0"
        izz="0" />
    </inertial>
    <visual>
      <origin
        xyz="0 0 0"
        rpy="0 0 0" />
      <geometry>
        <mesh
          filename="file://$(find cra_description)/meshes/cr20/Link1.STL" />
      </geometry>
      <material
        name="">
        <color
          rgba="0.792156862745098 0.819607843137255 0.933333333333333 1" />
      </material>
    </visual>
    <collision>
      <origin
        xyz="0 0 0"
        rpy="0 0 0" />
      <geometry>
        <mesh
          filename="file://$(find cra_description)/meshes/cr20/Link1.STL" />
      </geometry>
    </collision>
  </link>
  <joint
    name="joint1"
    type="revolute">
    <origin
      xyz="0 0 0.23"
      rpy="0 0 0" />
    <parent
      link="base_link" />
    <child
      link="Link1" />
    <axis
      xyz="0 0 1" />
    <limit
      lower="-6.28"
      upper="6.28"
      effort="0"
      velocity="0" />
  </joint>
  <link
    name="Link2">
    <inertial>
      <origin
        xyz="-0.828898669983325 -3.97165169431493E-07 0.115283168336158"
        rpy="0 0 0" />
      <mass
        value="0.000499668330610696" />
      <inertia
        ixx="0"
        ixy="0"
        ixz="0"
        iyy="0"
        iyz="0"
        izz="0" />
    </inertial>
    <visual>
      <origin
        xyz="0 0 0"
        rpy="0 0 0" />
      <geometry>
        <mesh
          filename="file://$(find cra_description)/meshes/cr20/Link2.STL" />
      </geometry>
      <material
        name="">
        <color
          rgba="0.792156862745098 0.819607843137255 0.933333333333333 1" />
      </material>
    </visual>
    <collision>
      <origin
        xyz="0 0 0"
        rpy="0 0 0" />
      <geometry>
        <mesh
          filename="file://$(find cra_description)/meshes/cr20/Link2.STL" />
      </geometry>
    </collision>
  </link>
  <joint
    name="joint2"
    type="revolute">
    <origin
      xyz="0 0 0"
      rpy="1.5708 1.5708 0" />
    <parent
      link="Link1" />
    <child
      link="Link2" />
    <axis
      xyz="0 0 1" />
    <limit
      lower="-6.28"
      upper="6.28"
      effort="0"
      velocity="0" />
  </joint>
  <link
    name="Link3">
    <inertial>
      <origin
        xyz="-0.746000007821945 1.07337005127015E-07 0.0757301295800403"
        rpy="0 0 0" />
      <mass
        value="0.00188731016390733" />
      <inertia
        ixx="0"
        ixy="0"
        ixz="0"
        iyy="0"
        iyz="0"
        izz="0" />
    </inertial>
    <visual>
      <origin
        xyz="0 0 0"
        rpy="0 0 0" />
      <geometry>
        <mesh
          filename="file://$(find cra_description)/meshes/cr20/Link3.STL" />
      </geometry>
      <material
        name="">
        <color
          rgba="0.792156862745098 0.819607843137255 0.933333333333333 1" />
      </material>
    </visual>
    <collision>
      <origin
        xyz="0 0 0"
        rpy="0 0 0" />
      <geometry>
        <mesh
          filename="file://$(find cra_description)/meshes/cr20/Link3.STL" />
      </geometry>
    </collision>
  </link>
  <joint
    name="joint3"
    type="revolute">
    <origin
      xyz="-0.8252 0 0.0468"
      rpy="0 0 0" />
    <parent
      link="Link2" />
    <child
      link="Link3" />
    <axis
      xyz="0 0 1" />
    <limit
      lower="-2.9"
      upper="2.9"
      effort="0"
      velocity="0" />
  </joint>
  <link
    name="Link4">
    <inertial>
      <origin
        xyz="1.09076486456641E-07 -0.0757301256894509 1.20551504334543E-08"
        rpy="0 0 0" />
      <mass
        value="0.00188731016585712" />
      <inertia
        ixx="0"
        ixy="0"
        ixz="0"
        iyy="0"
        iyz="0"
        izz="0" />
    </inertial>
    <visual>
      <origin
        xyz="0 0 0"
        rpy="0 0 0" />
      <geometry>
        <mesh
          filename="file://$(find cra_description)/meshes/cr20/Link4.STL" />
      </geometry>
      <material
        name="">
        <color
          rgba="0.792156862745098 0.819607843137255 0.933333333333333 1" />
      </material>
    </visual>
    <collision>
      <origin
        xyz="0 0 0"
        rpy="0 0 0" />
      <geometry>
        <mesh
          filename="file://$(find cra_description)/meshes/cr20/Link4.STL" />
      </geometry>
    </collision>
  </link>
  <joint
    name="joint4"
    type="revolute">
    <origin
      xyz="-0.746 0 0.1288"
      rpy="0 0 -1.5708" />
    <parent
      link="Link3" />
    <child
      link="Link4" />
    <axis
      xyz="0 0 1" />
    <limit
      lower="-6.28"
      upper="6.28"
      effort="0"
      velocity="0" />
  </joint>
  <link
    name="Link5">
    <inertial>
      <origin
        xyz="-1.06334234349293E-07 0.075730132822537 4.0368623999143E-09"
        rpy="0 0 0" />
      <mass
        value="0.00188731016390721" />
      <inertia
        ixx="0"
        ixy="0"
        ixz="0"
        iyy="0"
        iyz="0"
        izz="0" />
    </inertial>
    <visual>
      <origin
        xyz="0 0 0"
        rpy="0 0 0" />
      <geometry>
        <mesh
          filename="file://$(find cra_description)/meshes/cr20/Link5.STL" />
      </geometry>
      <material
        name="">
        <color
          rgba="0.792156862745098 0.819607843137255 0.933333333333333 1" />
      </material>
    </visual>
    <collision>
      <origin
        xyz="0 0 0"
        rpy="0 0 0" />
      <geometry>
        <mesh
          filename="file://$(find cra_description)/meshes/cr20/Link5.STL" />
      </geometry>
    </collision>
  </link>
  <joint
    name="joint5"
    type="revolute">
    <origin
      xyz="0 -0.1288 0"
      rpy="1.5708 0 0" />
    <parent
      link="Link4" />
    <child
      link="Link5" />
    <axis
      xyz="0 0 1" />
    <limit
      lower="-6.28"
      upper="6.28"
      effort="0"
      velocity="0" />
  </joint>
  <link
    name="Link6">
    <inertial>
      <origin
        xyz="0.0154576401891996 0.658802608062882 -0.213462466800391"
        rpy="0 0 0" />
      <mass
        value="0.00895254328755396" />
      <inertia
        ixx="0"
        ixy="0"
        ixz="0"
        iyy="0"
        iyz="0"
        izz="0" />
    </inertial>
    <visual>
      <origin
        xyz="0 0 0"
        rpy="0 0 0" />
      <geometry>
        <mesh
          filename="file://$(find cra_description)/meshes/cr20/Link6.STL" />
      </geometry>
      <material
        name="">
        <color
          rgba="0.792156862745098 0.819607843137255 0.933333333333333 1" />
      </material>
    </visual>
    <collision>
      <origin
        xyz="0 0 0"
        rpy="0 0 0" />
      <geometry>
        <mesh
          filename="file://$(find cra_description)/meshes/cr20/Link6.STL" />
      </geometry>
    </collision>
  </link>
  <joint
    name="joint6"
    type="revolute">
    <origin
      xyz="0 0.1365 0"
      rpy="-1.5708 0 0" />
    <parent
      link="Link5" />
    <child
      link="Link6" />
    <axis
      xyz="0 0 1" />
    <limit
      lower="-6.28"
      upper="6.28"
      effort="0"
      velocity="0" />
  </joint>
    <gazebo reference="Link1">
        <gravity>false</gravity>
        <selfCollide>true</selfCollide>
    </gazebo>
    <gazebo reference="Link2">
        <gravity>false</gravity>
        <selfCollide>true</selfCollide>
    </gazebo>
    <gazebo reference="Link3">
        <gravity>false</gravity>
        <selfCollide>true</selfCollide>
    </gazebo>
    <gazebo reference="Link4">
        <gravity>false</gravity>
        <selfCollide>true</selfCollide>
    </gazebo>
    <gazebo reference="Link5">
        <gravity>false</gravity>
        <selfCollide>true</selfCollide>
    </gazebo>
    <gazebo reference="Link6">
        <gravity>false</gravity>
        <selfCollide>true</selfCollide>
    </gazebo> 
    <!-- 在运行demo.launch.py时，需要注释这个ros2_control节点，因为它使用了xxx.ros2_control.xacro来生成了ros2_control节点-->
    <ros2_control name="GazeboSystem" type="system">
        <hardware>
            <plugin>gazebo_ros2_control/GazeboSystem</plugin>
        </hardware>
        <joint name="joint1">
            <command_interface name="position">
                <param name="min">-1</param>
                <param name="max">1</param>
            </command_interface>
            <state_interface name="position">
                <param name="initial_value">0.0</param>
            </state_interface>
            <state_interface name="velocity"/>
        </joint>
        <joint name="joint2">
            <command_interface name="position">
                <param name="min">-1</param>
                <param name="max">1</param>
            </command_interface>
            <state_interface name="position">
                <param name="initial_value">0.0</param>
            </state_interface>
            <state_interface name="velocity"/>
        </joint>
        <joint name="joint3">
            <command_interface name="position">
                <param name="min">-1</param>
                <param name="max">1</param>
            </command_interface>
            <state_interface name="position">
                <param name="initial_value">0.0</param>
            </state_interface>
            <state_interface name="velocity"/>
        </joint>
        <joint name="joint4">
            <command_interface name="position">
                <param name="min">-1</param>
                <param name="max">1</param>
            </command_interface>
            <state_interface name="position">
                <param name="initial_value">0.0</param>
            </state_interface>
            <state_interface name="velocity"/>
        </joint>
        <joint name="joint5">
            <command_interface name="position">
                <param name="min">-1</param>
                <param name="max">1</param>
            </command_interface>
            <state_interface name="position">
                <param name="initial_value">0.0</param>
            </state_interface>
            <state_interface name="velocity"/>
        </joint>
        <joint name="joint6">
            <command_interface name="position">
                <param name="min">-1</param>
                <param name="max">1</param>
            </command_interface>
            <state_interface name="position">
                <param name="initial_value">0.0</param>
            </state_interface>
            <state_interface name="velocity"/>
        </joint>
    </ros2_control>


    <gazebo>
        <plugin filename="libgazebo_ros2_control.so" name="gazebo_ros2_control">
            <parameters>$(find cr20_moveit)/config/ros2_controllers.yaml</parameters>
            <robot_param_node>robot_state_publisher</robot_param_node>
        </plugin>
    </gazebo>
</robot>