<?xml version="1.0"?>
<robot name="cr3_robot" xmlns:xacro="http://ros.org/wiki/xacro">
  <link name="dummy_link" />
  <link
    name="base_link">
    <inertial>
      <origin
        xyz="0.00230818905212046 -0.000732843557555838 0.028289656612971"
        rpy="0 0 0" />
      <mass
        value="0.648931294984644" />
      <inertia
        ixx="0.000749921651777976"
        ixy="4.21801992495725E-08"
        ixz="1.27081371753695E-06"
        iyy="0.000839640950438419"
        iyz="1.61611917342073E-07"
        izz="0.00112778981497252" />
    </inertial>
    <visual>
      <origin
        xyz="0 0 0"
        rpy="0 0 0" />
      <geometry>
        <mesh
          filename="file://$(find cra_description)/meshes/cr3/base_link.STL" />
      </geometry>
      <material
        name="">
        <color
          rgba="0.792156862745098 0.819607843137255 0.933333333333333 1" />
      </material>
    </visual>
    <collision>
      <origin
        xyz="0 0 0"
        rpy="0 0 0" />
      <geometry>
        <mesh
          filename="file://$(find cra_description)/meshes/cr3/base_link.STL" />
      </geometry>
    </collision>
  </link>
  <link  name="world"/>
  <joint name="world_joint" type="fixed">
    <origin xyz="0 0 0.03" rpy="0 0 0" />
    <parent link="world" />
    <child  link="dummy_link" />
  </joint>

  <joint name="dummy_joint" type="fixed">
      <parent link="dummy_link" />
      <child  link="base_link" />
    </joint>

  <link
    name="Link1">
    <inertial>
      <origin
        xyz="-3.67781721123111E-05 -0.00394376486631129 0.00364267890020981"
        rpy="0 0 0" />
      <mass
        value="1.31115064359517" />
      <inertia
        ixx="0.00319192385509536"
        ixy="-1.81661180744991E-06"
        ixz="-3.59316770697547E-07"
        iyy="0.00307821666880085"
        iyz="-1.88925967107205E-05"
        izz="0.00190896903282013" />
    </inertial>
    <visual>
      <origin
        xyz="0 0 0"
        rpy="0 0 0" />
      <geometry>
        <mesh
          filename="file://$(find cra_description)/meshes/cr3/J1.STL" />
      </geometry>
      <material
        name="">
        <color
          rgba="0.792156862745098 0.819607843137255 0.933333333333333 1" />
      </material>
    </visual>
    <collision>
      <origin
        xyz="0 0 0"
        rpy="0 0 0" />
      <geometry>
        <mesh
          filename="file://$(find cra_description)/meshes/cr3/J1.STL" />
      </geometry>
    </collision>
  </link>
  <joint
    name="joint1"
    type="revolute">
    <origin
      xyz="0 0 0.1348"
      rpy="0 0 -1.5708" />
    <parent
      link="base_link" />
    <child
      link="Link1" />
    <axis
      xyz="0 0 1" />
    <limit
      lower="-6.28"
      upper="6.28"
      effort="0"
      velocity="0" />
  </joint>
  <link
    name="Link2">
    <inertial>
      <origin
        xyz="-0.129228226099202 1.43480420269969E-05 0.133174339594273"
        rpy="0 0 0" />
      <mass
        value="3.40049600294342" />
      <inertia
        ixx="0.00665284748175434"
        ixy="1.79448081220597E-06"
        ixz="0.000635378334498705"
        iyy="0.0177342976210456"
        iyz="3.48633745916203E-07"
        izz="0.0150462633110018" />
    </inertial>
    <visual>
      <origin
        xyz="0 0 0"
        rpy="0 0 0" />
      <geometry>
        <mesh
          filename="file://$(find cra_description)/meshes/cr3/J2.STL" />
      </geometry>
      <material
        name="">
        <color
          rgba="0.792156862745098 0.819607843137255 0.933333333333333 1" />
      </material>
    </visual>
    <collision>
      <origin
        xyz="0 0 0"
        rpy="0 0 0" />
      <geometry>
        <mesh
          filename="file://$(find cra_description)/meshes/cr3/J2.STL" />
      </geometry>
    </collision>
  </link>
  <joint
    name="joint2"
    type="revolute">
    <origin
      xyz="0 0 0"
      rpy="1.5708 1.5708 0" />
    <parent
      link="Link1" />
    <child
      link="Link2" />
    <axis
      xyz="0 0 1" />
    <limit
      lower="-6.28"
      upper="6.28"
      effort="0"
      velocity="0" />
  </joint>
  <link
    name="Link3">
    <inertial>
      <origin
        xyz="-0.121267841067619 -5.95979094526938E-07 0.0103431444175778"
        rpy="0 0 0" />
      <mass
        value="2.18803928124499" />
      <inertia
        ixx="0.0031393454782363"
        ixy="2.60060285754048E-07"
        ixz="-0.000151120131479005"
        iyy="0.0236694689770697"
        iyz="3.67396297009222E-08"
        izz="0.0225795743545604" />
    </inertial>
    <visual>
      <origin
        xyz="0 0 0"
        rpy="0 0 0" />
      <geometry>
        <mesh
          filename="file://$(find cra_description)/meshes/cr3/J3.STL" />
      </geometry>
      <material
        name="">
        <color
          rgba="0.792156862745098 0.819607843137255 0.933333333333333 1" />
      </material>
    </visual>
    <collision>
      <origin
        xyz="0 0 0"
        rpy="0 0 0" />
      <geometry>
        <mesh
          filename="file://$(find cra_description)/meshes/cr3/J3.STL" />
      </geometry>
    </collision>
  </link>
  <joint
    name="joint3"
    type="revolute">
    <origin
      xyz="-0.274 0 0"
      rpy="0 0 0" />
    <parent
      link="Link2" />
    <child
      link="Link3" />
    <axis
      xyz="0 0 1" />
    <limit
      lower="-2.7039"
      upper="2.7039"
      effort="0"
      velocity="0" />
  </joint>
  <link
    name="Link4">
    <inertial>
      <origin
        xyz="1.66290133222139E-07 0.00345100795834197 -0.00287330777509653"
        rpy="0 0 0" />
      <mass
        value="0.842219175919104" />
      <inertia
        ixx="0.00173365879213697"
        ixy="-4.56469972647882E-09"
        ixz="-4.71044121344451E-10"
        iyy="0.000822485798327018"
        iyz="-9.31644060918737E-06"
        izz="0.00169454892249307" />
    </inertial>
    <visual>
      <origin
        xyz="0 0 0"
        rpy="0 0 0" />
      <geometry>
        <mesh
          filename="file://$(find cra_description)/meshes/cr3/J4.STL" />
      </geometry>
      <material
        name="">
        <color
          rgba="0.792156862745098 0.819607843137255 0.933333333333333 1" />
      </material>
    </visual>
    <collision>
      <origin
        xyz="0 0 0"
        rpy="0 0 0" />
      <geometry>
        <mesh
          filename="file://$(find cra_description)/meshes/cr3/J4.STL" />
      </geometry>
    </collision>
  </link>
  <joint
    name="joint4"
    type="continuous">
    <origin
      xyz="-0.23 0 0.1283"
      rpy="0 0 -1.5708" />
    <parent
      link="Link3" />
    <child
      link="Link4" />
    <axis
      xyz="0 0 -1" />
    <limit
      lower="-6.28"
      upper="6.28"
      effort="0"
      velocity="0" />
  </joint>
  <link
    name="Link5">
    <inertial>
      <origin
        xyz="1.66833832862591E-08 -0.00612503201462095 -0.00127182253112346"
        rpy="0 0 0" />
      <mass
        value="0.741136954868999" />
      <inertia
        ixx="0.00212858333835282"
        ixy="-3.05116516563277E-08"
        ixz="1.84588350647225E-08"
        iyy="0.000739514141681889"
        iyz="5.38479499117246E-05"
        izz="0.00208815449098071" />
    </inertial>
    <visual>
      <origin
        xyz="0 0 0"
        rpy="0 0 0" />
      <geometry>
        <mesh
          filename="file://$(find cra_description)/meshes/cr3/J5.STL" />
      </geometry>
      <material
        name="">
        <color
          rgba="0.792156862745098 0.819607843137255 0.933333333333333 1" />
      </material>
    </visual>
    <collision>
      <origin
        xyz="0 0 0"
        rpy="0 0 0" />
      <geometry>
        <mesh
          filename="file://$(find cra_description)/meshes/cr3/J5.STL" />
      </geometry>
    </collision>
  </link>
  <joint
    name="joint5"
    type="continuous">
    <origin
      xyz="0 -0.116 0"
      rpy="1.5708 0 0" />
    <parent
      link="Link4" />
    <child
      link="Link5" />
    <axis
      xyz="0 0 -1" />
    <limit
      lower="-6.28"
      upper="6.28"
      effort="0"
      velocity="0" />
  </joint>
  <link
    name="Link6">
    <inertial>
      <origin
        xyz="4.94378411169622E-11 9.37632286146517E-05 -0.019285436425589"
        rpy="0 0 0" />
      <mass
        value="0.157885369717385" />
      <inertia
        ixx="7.94006759268347E-05"
        ixy="4.66210912267001E-15"
        ixz="2.94413427013248E-14"
        iyy="7.91691792019657E-05"
        iyz="-9.61313747365421E-08"
        izz="0.000130860179835048" />
    </inertial>
    <visual>
      <origin
        xyz="0 0 0"
        rpy="0 0 0" />
      <geometry>
        <mesh
          filename="file://$(find cra_description)/meshes/cr3/J6.STL" />
      </geometry>
      <material
        name="">
        <color
          rgba="0.792156862745098 0.819607843137255 0.933333333333333 1" />
      </material>
    </visual>
    <collision>
      <origin
        xyz="0 0 0"
        rpy="0 0 0" />
      <geometry>
        <mesh
          filename="file://$(find cra_description)/meshes/cr3/J6.STL" />
      </geometry>
    </collision>
  </link>
  <joint
    name="joint6"
    type="revolute">
    <origin
      xyz="0 0.105 0"
      rpy="-1.5708 0 0" />
    <parent
      link="Link5" />
    <child
      link="Link6" />
    <axis
      xyz="0 0 -1" />
    <limit
      lower="-6.28"
      upper="6.28"
      effort="0"
      velocity="0" />
  </joint>
    <gazebo reference="base_link">
        <gravity>false</gravity>
        <selfCollide>true</selfCollide>
    </gazebo>
    <gazebo reference="Link1">
        <gravity>false</gravity>
        <selfCollide>true</selfCollide>
    </gazebo>
    <gazebo reference="Link2">
        <gravity>false</gravity>
        <selfCollide>true</selfCollide>
    </gazebo>
    <gazebo reference="Link3">
        <gravity>false</gravity>
        <selfCollide>true</selfCollide>
    </gazebo>
    <gazebo reference="Link4">
        <gravity>false</gravity>
        <selfCollide>true</selfCollide>
    </gazebo>
    <gazebo reference="Link5">
        <gravity>false</gravity>
        <selfCollide>true</selfCollide>
    </gazebo>
    <gazebo reference="Link6">
        <gravity>false</gravity>
        <selfCollide>true</selfCollide>
    </gazebo> 
    <!-- 在运行demo.launch.py时，需要注释这个ros2_control节点，因为它使用了xxx.ros2_control.xacro来生成了ros2_control节点-->
    <ros2_control name="GazeboSystem" type="system">
        <hardware>
            <plugin>gazebo_ros2_control/GazeboSystem</plugin>
        </hardware>
        <joint name="joint1">
            <command_interface name="position">
                <param name="min">-1</param>
                <param name="max">1</param>
            </command_interface>
            <state_interface name="position">
                <param name="initial_value">0.0</param>
            </state_interface>
            <state_interface name="velocity"/>
        </joint>
        <joint name="joint2">
            <command_interface name="position">
                <param name="min">-1</param>
                <param name="max">1</param>
            </command_interface>
            <state_interface name="position">
                <param name="initial_value">0.0</param>
            </state_interface>
            <state_interface name="velocity"/>
        </joint>
        <joint name="joint3">
            <command_interface name="position">
                <param name="min">-1</param>
                <param name="max">1</param>
            </command_interface>
            <state_interface name="position">
                <param name="initial_value">0.0</param>
            </state_interface>
            <state_interface name="velocity"/>
        </joint>
        <joint name="joint4">
            <command_interface name="position">
                <param name="min">-1</param>
                <param name="max">1</param>
            </command_interface>
            <state_interface name="position">
                <param name="initial_value">0.0</param>
            </state_interface>
            <state_interface name="velocity"/>
        </joint>
        <joint name="joint5">
            <command_interface name="position">
                <param name="min">-1</param>
                <param name="max">1</param>
            </command_interface>
            <state_interface name="position">
                <param name="initial_value">0.0</param>
            </state_interface>
            <state_interface name="velocity"/>
        </joint>
        <joint name="joint6">
            <command_interface name="position">
                <param name="min">-1</param>
                <param name="max">1</param>
            </command_interface>
            <state_interface name="position">
                <param name="initial_value">0.0</param>
            </state_interface>
            <state_interface name="velocity"/>
        </joint>
    </ros2_control>

    <gazebo>
        <plugin filename="libgazebo_ros2_control.so" name="gazebo_ros2_control">
            <parameters>$(find cr3_moveit)/config/ros2_controllers.yaml</parameters>
            <robot_param_node>robot_state_publisher</robot_param_node>
        </plugin>
    </gazebo>

</robot>