<?xml version="1.0" encoding="utf-8"?>
<!-- This URDF was automatically created by SolidWorks to URDF Exporter! Originally created by Stephen Brawner (brawner@gmail.com) 
     Commit Version: 1.6.0-4-g7f85cfe  Build Version: 1.6.7995.38578
     For more information, please see http://wiki.ros.org/sw_urdf_exporter -->
<robot
  name="cr10af_robot">
  <link name="dummy_link"/>
  <link
    name="base_link">
    <inertial>
      <origin
        xyz="-3.7612E-06 0.0011357 0.032382"
        rpy="0 0 0" />
      <mass
        value="2.01" />
      <inertia
        ixx="0.0042064"
        ixy="6.3817E-07"
        ixz="4.917E-07"
        iyy="0.0040224"
        iyz="1.8082E-05"
        izz="0.0067707" />
    </inertial>
    <visual>
      <origin
        xyz="0 0 0"
        rpy="0 0 0" />
      <geometry>
        <mesh
          filename="package://dobot_rviz/meshes/cr10af/base_link.STL" />
      </geometry>
      <material
        name="">
        <color
          rgba="0.59216 0.59216 0.59216 1" />
      </material>
    </visual>
    <collision>
      <origin
        xyz="0 0 0"
        rpy="0 0 0" />
      <geometry>
        <mesh
          filename="package://dobot_rviz/meshes/cr10af/base_link.STL" />
      </geometry>
    </collision>
  </link>
  <joint name="dummy_joint" type="fixed">
      <parent link="dummy_link" />
      <child  link="base_link" />
    </joint>
  <link
    name="J1">
    <inertial>
      <origin
        xyz="-5.9674E-07 -0.011961 0.10128"
        rpy="0 0 0" />
      <mass
        value="8.97" />
      <inertia
        ixx="0.020878"
        ixy="-2.467E-08"
        ixz="9.3616E-08"
        iyy="0.018796"
        iyz="0.00012915"
        izz="0.015433" />
    </inertial>
    <visual>
      <origin
        xyz="0 0 0"
        rpy="0 0 0" />
      <geometry>
        <mesh
          filename="package://dobot_rviz/meshes/cr10af/J1.STL" />
      </geometry>
      <material
        name="">
        <color
          rgba="0.79216 0.81961 0.93333 1" />
      </material>
    </visual>
    <collision>
      <origin
        xyz="0 0 0"
        rpy="0 0 0" />
      <geometry>
        <mesh
          filename="package://dobot_rviz/meshes/cr10af/J1.STL" />
      </geometry>
    </collision>
  </link>
  <joint
    name="joint1"
    type="revolute">
    <origin
      xyz="0 0 0.079"
      rpy="0 0 0" />
    <parent
      link="base_link" />
    <child
      link="J1" />
    <axis
      xyz="0 0 1" />
    <limit
      lower="-6.2831"
      upper="6.2831"
      effort="0"
      velocity="0" />
  </joint>
  <link
    name="J2">
    <inertial>
      <origin
        xyz="2.1881E-07 -0.093266 0.24604"
        rpy="0 0 0" />
      <mass
        value="16.9" />
      <inertia
        ixx="0.60997"
        ixy="3.4182E-07"
        ixz="-1.0197E-06"
        iyy="0.60329"
        iyz="0.0035505"
        izz="0.034" />
    </inertial>
    <visual>
      <origin
        xyz="0 0 0"
        rpy="0 0 0" />
      <geometry>
        <mesh
          filename="package://dobot_rviz/meshes/cr10af/J2.STL" />
      </geometry>
      <material
        name="">
        <color
          rgba="0.79216 0.81961 0.93333 1" />
      </material>
    </visual>
    <collision>
      <origin
        xyz="0 0 0"
        rpy="0 0 0" />
      <geometry>
        <mesh
          filename="package://dobot_rviz/meshes/cr10af/J2.STL" />
      </geometry>
    </collision>
  </link>
  <joint
    name="joint2"
    type="revolute">
    <origin
      xyz="0 -0.102 0.0975"
      rpy="0 0 0" />
    <parent
      link="J1" />
    <child
      link="J2" />
    <axis
      xyz="0 -1 0" />
    <limit
      lower="-6.2831"
      upper="6.2831"
      effort="0"
      velocity="0" />
  </joint>
  <link
    name="J3">
    <inertial>
      <origin
        xyz="-9.4859E-08 0.05571 0.27104"
        rpy="0 0 0" />
      <mass
        value="5.47" />
      <inertia
        ixx="0.23209"
        ixy="-6.3966E-09"
        ixz="-3.007E-07"
        iyy="0.23101"
        iyz="0.0026298"
        izz="0.0068608" />
    </inertial>
    <visual>
      <origin
        xyz="0 0 0"
        rpy="0 0 0" />
      <geometry>
        <mesh
          filename="package://dobot_rviz/meshes/cr10af/J3.STL" />
      </geometry>
      <material
        name="">
        <color
          rgba="0.79216 0.81961 0.93333 1" />
      </material>
    </visual>
    <collision>
      <origin
        xyz="0 0 0"
        rpy="0 0 0" />
      <geometry>
        <mesh
          filename="package://dobot_rviz/meshes/cr10af/J3.STL" />
      </geometry>
    </collision>
  </link>
  <joint
    name="joint3"
    type="revolute">
    <origin
      xyz="0 -0.015 0.607"
      rpy="0 0 0" />
    <parent
      link="J2" />
    <child
      link="J3" />
    <axis
      xyz="0 1 0" />
    <limit
      lower="-2.7925"
      upper="2.7925"
      effort="0"
      velocity="0" />
  </joint>
  <link
    name="J4">
    <inertial>
      <origin
        xyz="2.8401E-07 -0.060432 -0.010119"
        rpy="0 0 0" />
      <mass
        value="2.6" />
      <inertia
        ixx="0.0027385"
        ixy="-3.2473E-09"
        ixz="-1.4591E-09"
        iyy="0.0025464"
        iyz="6.9168E-05"
        izz="0.0014808" />
    </inertial>
    <visual>
      <origin
        xyz="0 0 0"
        rpy="0 0 0" />
      <geometry>
        <mesh
          filename="package://dobot_rviz/meshes/cr10af/J4.STL" />
      </geometry>
      <material
        name="">
        <color
          rgba="0.79216 0.81961 0.93333 1" />
      </material>
    </visual>
    <collision>
      <origin
        xyz="0 0 0"
        rpy="0 0 0" />
      <geometry>
        <mesh
          filename="package://dobot_rviz/meshes/cr10af/J4.STL" />
      </geometry>
    </collision>
  </link>
  <joint
    name="joint4"
    type="revolute">
    <origin
      xyz="0 -0.0075 0.568"
      rpy="0 0 0" />
    <parent
      link="J3" />
    <child
      link="J4" />
    <axis
      xyz="0 -1 0" />
    <limit
      lower="-6.2831"
      upper="6.2831"
      effort="0"
      velocity="0" />
  </joint>
  <link
    name="J5">
    <inertial>
      <origin
        xyz="-5.8252E-07 0.016958 0.053728"
        rpy="0 0 0" />
      <mass
        value="2.6" />
      <inertia
        ixx="0.0030944"
        ixy="-3.8416E-08"
        ixz="-1.9864E-08"
        iyy="0.0013893"
        iyz="6.7569E-05"
        izz="0.0030186" />
    </inertial>
    <visual>
      <origin
        xyz="0 0 0"
        rpy="0 0 0" />
      <geometry>
        <mesh
          filename="package://dobot_rviz/meshes/cr10af/J5.STL" />
      </geometry>
      <material
        name="">
        <color
          rgba="0.79216 0.81961 0.93333 1" />
      </material>
    </visual>
    <collision>
      <origin
        xyz="0 0 0"
        rpy="0 0 0" />
      <geometry>
        <mesh
          filename="package://dobot_rviz/meshes/cr10af/J5.STL" />
      </geometry>
    </collision>
  </link>
  <joint
    name="joint5"
    type="revolute">
    <origin
      xyz="0 -0.066501 0.068"
      rpy="0 0 0" />
    <parent
      link="J4" />
    <child
      link="J5" />
    <axis
      xyz="0 0 1" />
    <limit
      lower="-6.2831"
      upper="6.2831"
      effort="0"
      velocity="0" />
  </joint>
  <link
    name="J6">
    <inertial>
      <origin
        xyz="7.3738E-09 -0.028312 6.3267E-05"
        rpy="0 0 0" />
      <mass
        value="0.4" />
      <inertia
        ixx="0.00027773"
        ixy="-2.9004E-11"
        ixz="1.4444E-10"
        iyy="0.00035983"
        iyz="3.5391E-07"
        izz="0.00027649" />
    </inertial>
    <visual>
      <origin
        xyz="0 0 0"
        rpy="0 0 0" />
      <geometry>
        <mesh
          filename="package://dobot_rviz/meshes/cr10af/J6.STL" />
      </geometry>
      <material
        name="">
        <color
          rgba="1 1 1 1" />
      </material>
    </visual>
    <collision>
      <origin
        xyz="0 0 0"
        rpy="0 0 0" />
      <geometry>
        <mesh
          filename="package://dobot_rviz/meshes/cr10af/J6.STL" />
      </geometry>
    </collision>
  </link>
  <joint
    name="joint6"
    type="revolute">
    <origin
      xyz="0 -0.066499 0.057"
      rpy="0 0 0" />
    <parent
      link="J5" />
    <child
      link="J6" />
    <axis
      xyz="0 -1 0" />
    <limit
      lower="-6.2831"
      upper="6.2831"
      effort="0"
      velocity="0" />
  </joint>
</robot>
