<?xml version="1.0" encoding="utf-8"?>
<robot
  name="cr30h_robot">
  <link name="dummy_link"/>
  <link
    name="base_link">
    <inertial>
      <origin
        xyz="-1.78212555854348E-05 0.00033084177723393 0.0931967971971018"
        rpy="0 0 0" />
      <mass
        value="3.62558882362798" />
      <inertia
        ixx="0.0188475732650718"
        ixy="-1.37313910460006E-06"
        ixz="-4.46309791436276E-06"
        iyy="0.0186121426737853"
        iyz="7.17633946778761E-05"
        izz="0.0272514849943692" />
    </inertial>
    <visual>
      <origin
        xyz="0 0 0"
        rpy="0 0 0" />
      <geometry>
        <mesh
          filename="package://dobot_rviz/meshes/cr30h/base_link.STL" />
      </geometry>
      <material
        name="">
        <color
          rgba="1 1 1 1" />
      </material>
    </visual>
    <collision>
      <origin
        xyz="0 0 0"
        rpy="0 0 0" />
      <geometry>
        <mesh
          filename="package://dobot_rviz/meshes/cr30h/base_link.STL" />
      </geometry>
    </collision>
  </link>
  <joint name="dummy_joint" type="fixed">
      <parent link="dummy_link" />
      <child  link="base_link" />
    </joint>
  <link
    name="Link1">
    <inertial>
      <origin
        xyz="0.0685683156633234 6.45617962612603E-06 0.0352475118413176"
        rpy="0 0 0" />
      <mass
        value="14.4147388577882" />
      <inertia
        ixx="0.117399762147082"
        ixy="-1.3100541842346E-07"
        ixz="0.0356431430537303"
        iyy="0.187002726933162"
        iyz="6.38547998155339E-07"
        izz="0.161038602803283" />
    </inertial>
    <visual>
      <origin
        xyz="0 0 0"
        rpy="0 0 0" />
      <geometry>
        <mesh
          filename="package://dobot_rviz/meshes/cr30h/Link1.STL" />
      </geometry>
      <material
        name="">
        <color
          rgba="1 1 1 1" />
      </material>
    </visual>
    <collision>
      <origin
        xyz="0 0 0"
        rpy="0 0 0" />
      <geometry>
        <mesh
          filename="package://dobot_rviz/meshes/cr30h/Link1.STL" />
      </geometry>
    </collision>
  </link>
  <joint
    name="joint1"
    type="revolute">
    <origin
      xyz="0 0 0.386"
      rpy="1.5708 1.5708 0" />
    <parent
      link="base_link" />
    <child
      link="Link1" />
    <axis
      xyz="-1 0 0" />
    <limit
      lower="-6.28"
      upper="6.28"
      effort="0"
      velocity="0" />
  </joint>
  <link
    name="Link2">
    <inertial>
      <origin
        xyz="-0.398905663494017 1.92684404646904E-06 0.340471375570728"
        rpy="0 0 0" />
      <mass
        value="35.1837906440538" />
      <inertia
        ixx="0.274172849710145"
        ixy="-2.79808731990376E-05"
        ixz="0.0178158997550407"
        iyy="3.75626158130774"
        iyz="7.44413946972762E-06"
        izz="3.66050132171213" />
    </inertial>
    <visual>
      <origin
        xyz="0 0 0"
        rpy="0 0 0" />
      <geometry>
        <mesh
          filename="package://dobot_rviz/meshes/cr30h/Link2.STL" />
      </geometry>
      <material
        name="">
        <color
          rgba="1 1 1 1" />
      </material>
    </visual>
    <collision>
      <origin
        xyz="0 0 0"
        rpy="0 0 0" />
      <geometry>
        <mesh
          filename="package://dobot_rviz/meshes/cr30h/Link2.STL" />
      </geometry>
    </collision>
  </link>
  <joint
    name="joint2"
    type="revolute">
    <origin
      xyz="0 0 0"
      rpy="0 0 0" />
    <parent
      link="Link1" />
    <child
      link="Link2" />
    <axis
      xyz="0 0 1" />
    <limit
      lower="-6.28"
      upper="6.28"
      effort="0"
      velocity="0" />
  </joint>
  <link
    name="Link3">
    <inertial>
      <origin
        xyz="-0.311995849028024 -2.45961873714507E-06 0.0755143467372146"
        rpy="0 0 0" />
      <mass
        value="15.319320357705" />
      <inertia
        ixx="0.0549431220959"
        ixy="-7.19675342087617E-06"
        ixz="-0.0219294614712449"
        iyy="1.16897867168856"
        iyz="1.09525212299586E-06"
        izz="1.15939372786569" />
    </inertial>
    <visual>
      <origin
        xyz="0 0 0"
        rpy="0 0 0" />
      <geometry>
        <mesh
          filename="package://dobot_rviz/meshes/cr30h/Link3.STL" />
      </geometry>
      <material
        name="">
        <color
          rgba="1 1 1 1" />
      </material>
    </visual>
    <collision>
      <origin
        xyz="0 0 0"
        rpy="0 0 0" />
      <geometry>
        <mesh
          filename="package://dobot_rviz/meshes/cr30h/Link3.STL" />
      </geometry>
    </collision>
  </link>
  <joint
    name="joint3"
    type="revolute">
    <origin
      xyz="-0.84 0 0"
      rpy="0 0 0" />
    <parent
      link="Link2" />
    <child
      link="Link3" />
    <axis
      xyz="1.0869E-05 -5.499E-05 -1" />
    <limit
      lower="-2.79"
      upper="2.79"
      effort="0"
      velocity="0" />
  </joint>
  <link
    name="Link4">
    <inertial>
      <origin
        xyz="-8.57425838810129E-07 -0.0319217802585721 -0.0137198757861597"
        rpy="0 0 0" />
      <mass
        value="2.61293279831353" />
      <inertia
        ixx="0.0104099655758254"
        ixy="4.37316634029077E-08"
        ixz="-1.41265169952098E-07"
        iyy="0.00671272940307182"
        iyz="0.00125622535616839"
        izz="0.00920549791565436" />
    </inertial>
    <visual>
      <origin
        xyz="0 0 0"
        rpy="0 0 0" />
      <geometry>
        <mesh
          filename="package://dobot_rviz/meshes/cr30h/Link4.STL" />
      </geometry>
      <material
        name="">
        <color
          rgba="1 1 1 1" />
      </material>
    </visual>
    <collision>
      <origin
        xyz="0 0 0"
        rpy="0 0 0" />
      <geometry>
        <mesh
          filename="package://dobot_rviz/meshes/cr30h/Link4.STL" />
      </geometry>
    </collision>
  </link>
  <joint
    name="joint4"
    type="revolute">
    <origin
      xyz="-0.74 0 0.277"
      rpy="0 0 -1.5708" />
    <parent
      link="Link3" />
    <child
      link="Link4" />
    <axis
      xyz="0 0 1" />
    <limit
      lower="-6.28"
      upper="6.28"
      effort="0"
      velocity="0" />
  </joint>
  <link
    name="Link5">
    <inertial>
      <origin
        xyz="8.46129739418622E-07 0.0319217771350954 -0.0137198627897681"
        rpy="0 0 0" />
      <mass
        value="2.61293334766506" />
      <inertia
        ixx="0.010409967784472"
        ixy="4.24619055119814E-08"
        ixz="1.41652897308557E-07"
        iyy="0.0067127314928378"
        iyz="-0.00125622463177166"
        izz="0.00920549783104573" />
    </inertial>
    <visual>
      <origin
        xyz="0 0 0"
        rpy="0 0 0" />
      <geometry>
        <mesh
          filename="package://dobot_rviz/meshes/cr30h/Link5.STL" />
      </geometry>
      <material
        name="">
        <color
          rgba="1 1 1 1" />
      </material>
    </visual>
    <collision>
      <origin
        xyz="0 0 0"
        rpy="0 0 0" />
      <geometry>
        <mesh
          filename="package://dobot_rviz/meshes/cr30h/Link5.STL" />
      </geometry>
    </collision>
  </link>
  <joint
    name="joint5"
    type="revolute">
    <origin
      xyz="0 -0.22 0"
      rpy="1.5708 0 0" />
    <parent
      link="Link4" />
    <child
      link="Link5" />
    <axis
      xyz="0 0 1" />
    <limit
      lower="-6.28"
      upper="6.28"
      effort="0"
      velocity="0" />
  </joint>
  <link
    name="Link6">
    <inertial>
      <origin
        xyz="-1.48486365630313E-05 -3.88625128908693E-05 -0.0440280633098416"
        rpy="0 0 0" />
      <mass
        value="0.927683989477254" />
      <inertia
        ixx="0.00138402817840661"
        ixy="-4.97862571992853E-09"
        ixz="7.27343797024477E-09"
        iyy="0.00137309138053452"
        iyz="-6.18606261796794E-07"
        izz="0.00187822403965052" />
    </inertial>
    <visual>
      <origin
        xyz="0 0 0"
        rpy="0 0 0" />
      <geometry>
        <mesh
          filename="package://dobot_rviz/meshes/cr30h/Link6.STL" />
      </geometry>
      <material
        name="">
        <color
          rgba="1 1 1 1" />
      </material>
    </visual>
    <collision>
      <origin
        xyz="0 0 0"
        rpy="0 0 0" />
      <geometry>
        <mesh
          filename="package://dobot_rviz/meshes/cr30h/Link6.STL" />
      </geometry>
    </collision>
  </link>
  <joint
    name="joint6"
    type="revolute">
    <origin
      xyz="0 0.211 0"
      rpy="-1.5708 0 0" />
    <parent
      link="Link5" />
    <child
      link="Link6" />
    <axis
      xyz="0 0 -1" />
    <limit
      lower="-6.28"
      upper="6.28"
      effort="0"
      velocity="0" />
  </joint>
</robot>